Workbook

Sheet RÍGIDO-Anexo 2 (A)
AY1: Anexo 2
O2: "MAPA CURRICULAR"
O3: INSTITUCIÓN: UNIVERSIDAD INTERNACIONAL DE GUANAJUATO
O4: PLAN DE ESTUDIOS: LICENCIATURA EN NUTRICIÓN (MODALIDAD ESCOLARIZADA)
A6: CICLO
A7: PRIMER SEMESTRE | C7: LNSHE-101 | G7: OBLIGATORIA | I7: LNCS-102 | M7: OBLIGATORIA | O7: LNCA-103 | S7: OBLIGATORIA | U7: LNCA-104 | Y7: OBLIGATORIA | AA7: LNCS-105 | AE7: OBLIGATORIA
C8: Humanística I. Identidad universitaria. | I8: Anatomía y fisiología humana | O8: Química de la nutrición | U8: Biología celular | AA8: Fundamentos de la nutrición | AY8: HA | AZ8: =C11+I11+O11+U11+AA11+AG11 -> 640
AY9: HI | AZ9: =E11+K11+Q11+W11+AC11 -> 320
AY10: CR | AZ10: =F11+L11+R11+X11+AD11 -> 60
C11: 128 | E11: 64 | F11: 12 | G11: A | I11: 128 | K11: 64 | L11: 12 | M11: A/L | O11: 128 | Q11: 64 | R11: 12 | S11: A/L | U11: 128 | W11: 64 | X11: 12 | Y11: A/L | AA11: 128 | AC11: 64 | AD11: 12 | AE11: A
A13: SEGUNDO SEMESTRE | C13: LNSHE-206 | F13: LNSHE-101 | G13: OBLIGATORIA | I13: LNCS-207 | M13: OBLIGATORIA | O13: LNCS-208 | S13: OBLIGATORIA | U13: LNSHE-209 | Y13: OBLIGATORIA | AA13: LNCA-210 | AE13: OBLIGATORIA | AG13: LNGII-211 | AK13: OBLIGATORIA
C14: Humanística II. La persona y su compromiso con el entorno y la sociedad. | I14: Fisiología de la nutrición | O14: Introducción a la evaluación del estado nutricional | U14: Antropología y soberanía alimentaria | AA14: Química de alimentos | AG14: Principios de la administración | AY14: HA | AZ14: =C17+I17+O17+U17+AA17+AG17 -> 768
AY15: HI | AZ15: =E17+K17+Q17+W17+AC17+AI17 -> 384
AY16: CR | AZ16: =F17+L17+R17+X17+AD17+AJ17 -> 72
C17: 128 | E17: 64 | F17: 12 | G17: A | I17: 128 | K17: 64 | L17: 12 | M17: A/L | O17: 128 | Q17: 64 | R17: 12 | S17: A/L | U17: 128 | W17: 64 | X17: 12 | Y17: A | AA17: 128 | AC17: 64 | AD17: 12 | AE17: A/L | AG17: 128 | AI17: 64 | AJ17: 12 | AK17: A
A19: TERCER SEMESTRE | C19: LNSHE-312 | F19: LNSHE-206 | G19: OBLIGATORIA | I19: LNSHE-313 | M19: OBLIGATORIA | O19: LNCA-314 | S19: OBLIGATORIA | U19: LNCS-315 | Y19: OBLIGATORIA | AA19: LNCS-316 | AE19: OBLIGATORIA | AG19: LNSHE-317 | AK19: OBLIGATORIA | AM19: LNCA-318 | AQ19: OBLIGATORIA | AS19: LNGII-319 | AW19: OBLIGATORIA
C20: Humanística III. La persona y el compromiso con su ser trascendente. | I20: Desarrollo Social | O20: Alimentos y bebidas nacionales e internacionales | U20: Bioquímica metabólica I | AA20: Nutrición y dietética en el ciclo de la vida I | AG20: Psicología social y conducta alimentaria | AM20: Microbiología de alimentos | AS20: Administración de servicios de alimentos | AY20: HA | AZ20: =+C23+I23+O23+U23+AA23+AG23+AM23+AS23 -> 768
AY21: HI | AZ21: =E23+K23+Q23+W23+AC23+AI23+AO23+AU23 -> 384
AY22: CR | AZ22: =F23+L23+R23+X23+AD23+AJ23+AP23+AV23 -> 72
C23: 80 | E23: 40 | F23: 7.5 | G23: A | I23: 80 | K23: 40 | L23: 7.5 | M23: A | O23: 112 | Q23: 56 | R23: 10.5 | S23: A/L | U23: 112 | W23: 56 | X23: 10.5 | Y23: A | AA23: 112 | AC23: 56 | AD23: 10.5 | AE23: A | AG23: 80 | AI23: 40 | AJ23: 7.5 | AK23: A/CC | AM23: 112 | AO23: 56 | AP23: 10.5 | AQ23: A/L | AS23: 80 | AU23: 40 | AV23: 7.5 | AW23: A
A25: CUARTO SEMESTRE | C25: LNSHE-420 | F25: LNSHE-312 | G25: OBLIGATORIA | I25: LNSHE-421 | M25: OBLIGATORIA | O25: LNCS-422 | R25: LNCS-315 | S25: OBLIGATORIA | U25: LNCS-423 | X25: LNCS-316 | Y25: OBLIGATORIA | AA25: LNCA-424 | AE25: OBLIGATORIA | AG25: LNCA-425 | AK25: OBLIGATORIA | AM25: LNGII-426 | AQ25: OBLIGATORIA
C26: Humanística IV. La persona y el compromiso con el otro cercano | I26: Pensamiento crítico | O26: Bioquímica metabólica II | U26: Nutrición y dietética en el ciclo de la vida II | AA26: Producción de alimentos y técnicas culinarias | AG26: Análisis de alimentos | AM26: Prácticas en servicios de alimentos | AY26: HA | AZ26: =C29+I29+O29+U29+AA29+AG29+AM29 -> 768
AY27: HI | AZ27: =E29+K29+Q29+W29+AC29+AI29+AO29 -> 384
AY28: CR | AZ28: =F29+L29+R29+X29+AD29+AJ29+AP29 -> 72
C29: 96 | E29: 48 | F29: 9 | G29: A | I29: 96 | K29: 48 | L29: 9 | M29: A/CC | O29: 96 | Q29: 48 | R29: 9 | S29: A/L | U29: 96 | W29: 48 | X29: 9 | Y29: A | AA29: 128 | AC29: 64 | AD29: 12 | AE29: A/L | AG29: 128 | AI29: 64 | AJ29: 12 | AK29: A/L | AM29: 128 | AO29: 64 | AP29: 12 | AQ29: A/CL
A31: QUINTO SEMESTRE | C31: LNSHE-527 | F31: LNSHE-420 | G31: OBLIGATORIA | I31: LNSHE-528 | M31: OBLIGATORIA | O31: LNGII-529 | S31: OBLIGATORIA | U31: LNCS-530 | Y31: OBLIGATORIA | AA31: LNCS-531 | AE31: OBLIGATORIA | AG31: LNSHE-532 | AK31: OBLIGATORIA | AM31: LNCA-533 | AQ31: OBLIGATORIA | AS31: LNCS-534 | AW31: OBLIGATORIA
C32: Humanística V. La persona y su compromiso consigo misma | I32: Sistemas económicos y política pública | O32: Interdisciplinaria I. Dignidad humana | U32: Fisiopatología | AA32: Proceso de cuidado nutricional | AG32: Toma de decisiones ético-profesionales | AM32: Tecnología de alimentos con compromiso social | AS32: Calidad de la atención y seguridad del paciente | AY32: HA | AZ32: =+C35+I35+O35+U35+AA35+AG35+AM35+AS35 -> 768
AY33: HI | AZ33: =+E35+K35+Q35+W35+AC35+AI35+AO35+AU35 -> 384
AY34: CR | AZ34: =+F35+L35+R35+X35+AD35+AJ35+AP35+AV35 -> 72
C35: 80 | E35: 40 | F35: 7.5 | G35: A | I35: 96 | K35: 48 | L35: 9 | M35: A | O35: 96 | Q35: 48 | R35: 9 | S35: A | U35: 96 | W35: 48 | X35: 9 | Y35: A/L | AA35: 112 | AC35: 56 | AD35: 10.5 | AE35: A | AG35: 80 | AI35: 40 | AJ35: 7.5 | AK35: A | AM35: 96 | AO35: 48 | AP35: 9 | AQ35: A/L | AS35: 112 | AU35: 56 | AV35: 10.5 | AW35: A/L
A37: SEXTO SEMESTRE | C37: LNCS-635 | G37: OBLIGATORIA | I37: LNGII-636 | L37: LNGII-529 | M37: OBLIGATORIA | O37: LNGII-637 | S37: OBLIGATORIA | U37: LNCS-638 | Y37: OBLIGATORIA | AA37: LNCS-639 | AE37: OBLIGATORIA | AG37: LNSHE-640 | AK37: OBLIGATORIA | AM37: LNCA-641 | AQ37: OBLIGATORIA | AS37: LNCS-642 | AW37: OBLIGATORIA
C38: Nutrición en situaciones especiales de salud | I38: Interdisciplinaria II. Ética | O38: Metodología de la investigación | U38: Clínica de dietoterapia I | AA38: Farmacología aplicada a la nutrición | AG38: Salud y Políticas Públicas aplicadas a la nutrición | AM38: Desarrollo e innovación de productos alimentarios | AS38: Nutrición y ejercicio físico | AY38: HA | AZ38: =+C41+I41+O41+U41+AA41+AG41+AM41+AS41 -> 768
AY39: HI | AZ39: =+E41+K41+Q41+W41+AC41+AI41+AO41+AU41 -> 384
AY40: CR | AZ40: =+F41+L41+R41+X41+AD41+AJ41+AP41+AV41 -> 72
C41: 112 | E41: 56 | F41: 10.5 | G41: A | I41: 80 | K41: 40 | L41: 7.5 | M41: A | O41: 80 | Q41: 40 | R41: 7.5 | S41: A | U41: 112 | W41: 56 | X41: 10.5 | Y41: A/L | AA41: 96 | AC41: 48 | AD41: 9 | AE41: A/L | AG41: 80 | AI41: 40 | AJ41: 7.5 | AK41: A/CC | AM41: 112 | AO41: 56 | AP41: 10.5 | AQ41: A/L | AS41: 96 | AU41: 48 | AV41: 9 | AW41: A/L
A43: SÉPTIMO SEMESTRE | C43: LNGII-743 | F43: LNGII-636 | G43: OBLIGATORIA | I43: LNGII-744 | M43: OBLIGATORIA | O43: LNCS-745 | R43: LNCS-638 | S43: OBLIGATORIA | U43: LNSHE-746 | Y43: OBLIGATORIA | AA43: LNCA-747 | AE43: OBLIGATORIA | AG43: LNCA-748 | AK43: OBLIGATORIA | AM43: LNGII-749 | AQ43: OBLIGATORIA | AS43: LNCA-750 | AW43: OBLIGATORIA
C44: Interdisciplinaria III. Sostenibilidad | I44: Seminario de investigación | O44: Clínica de dietoterapia II | U44: Estrategias para la educación en salud y nutrición | AA44: Alimentación sostenible | AG44: Aseguramiento de calidad e inocuidad de alimentos | AM44: Emprendimiento | AS44: Alimentos funcionales | AY44: HA | AZ44: =+C47+I47+O47+U47+AA47+AG47+AM47+AS47 -> 768
AY45: HI | AZ45: =+E47+K47+Q47+W47+AC47+AI47+AO47+AU47 -> 384
AY46: CR | AZ46: =+F47+L47+R47+X47+AD47+AJ47+AP47+AV47 -> 72
C47: 80 | E47: 40 | F47: 7.5 | G47: A | I47: 112 | K47: 56 | L47: 10.5 | M47: A/C | O47: 128 | Q47: 64 | R47: 12 | S47: A/L | U47: 96 | W47: 48 | X47: 9 | Y47: A | AA47: 80 | AC47: 40 | AD47: 7.5 | AE47: A | AG47: 96 | AI47: 48 | AJ47: 9 | AK47: A/CL | AM47: 80 | AO47: 40 | AP47: 7.5 | AQ47: A | AS47: 96 | AU47: 48 | AV47: 9 | AW47: A/L
...

Sheet OPTATIVAS-Anexo 2 (A)
H1: Anexo 2
C2: "MAPA CURRICULAR"
B4: ASIGNATURAS OPTATIVAS
A5: CICLO | B5: ASIGNATURA O UNIDAD DE APRENDIZAJE | C5: CLAVE | D5: SERIACIÓN | E5: HORAS | G5: CRÉDITOS | H5: INSTALACIONES
E6: CON ACADÉMICO | F6: INDEPENDIENTES
B16: REQUERIMIENTOS MÍNIMOS PARA LAS ASIGNATURAS OPTATIVAS
B17: HORAS BAJO CONDUCCIÓN DE UN ACADÉMICO | F17: =SUM(E7:E12) -> 0
B18: CRÉDITOS | F18: =SUM(G7:G12) -> 0
B22: TOTAL DE ASIGNATURAS QUE INTEGRAN EL PLAN DE ESTUDIOS
B23: TIPO DE ASIGNATURA | C23: HORAS BAJO CONDUCCIÓN DE UN ACADÉMICO | E23: HORAS INDEPENDIENTES | G23: CRÉDITOS
B24: OBLIGATORIAS | C24: =+'RÍGIDO-Anexo 2 (A)'!AK59 -> 6016 | E24: =+'RÍGIDO-Anexo 2 (A)'!AK60 -> 3008 | G24: =+'RÍGIDO-Anexo 2 (A)'!AK61 -> 564
B25: OPTATIVAS | C25: =SUM(E7:E12) -> 0 | E25: =SUM(F7:F12) -> 0 | G25: =SUM(G7:G12) -> 0
B27: SUMAS TOTALES | C27: =SUM(C24,C25) -> 6016 | E27: =SUM(E24,E25) -> 3008 | G27: =SUM(G24,G25) -> 564

Sheet FLEXIBLE-Anexo 2 (B)
H1: Anexo 2
C2: "MAPA CURRICULAR"
B4: DISEÑO CURRICULAR FLEXIBLE POR ÁREAS
A5: ÁREA (O MÓDULO) | B5: ASIGNATURA O UNIDAD DE APRENDIZAJE | C5: CLAVE | D5: SERIACIÓN | E5: HORAS | G5: CRÉDITOS | H5: INSTALACIONES
E6: CON ACADÉMICO | F6: INDEPENDIENTES
A7: Ciencias de la salud y nutrición | B7: Anatomía y fisiología humana | C7: LNCS-102 | E7: =+'RÍGIDO-Anexo 2 (A)'!I11 -> 128 | F7: =+E7/2 -> 64 | G7: =(E7+F7)*0.0625 -> 12 | H7: Aula / Laboratorio
B8: Fundamentos de la nutrición | C8: LNCS-105 | E8: =+'RÍGIDO-Anexo 2 (A)'!AA11 -> 128 | F8: =+E8/2 -> 64 | G8: =(E8+F8)*0.0625 -> 12 | H8: Aula
B9: Fisiología de la nutrición | C9: LNCS-207 | E9: =+'RÍGIDO-Anexo 2 (A)'!I17 -> 128 | F9: =+E9/2 -> 64 | G9: =(E9+F9)*0.0625 -> 12 | H9: Aula / Laboratorio
B10: Introducción a la evaluación del estado nutricio | C10: LNCS-208 | E10: =+'RÍGIDO-Anexo 2 (A)'!O17 -> 128 | F10: =+E10/2 -> 64 | G10: =(E10+F10)*0.0625 -> 12 | H10: Aula / Laboratorio
B11: Bioquímica metabólica I | C11: LNCS-315 | E11: =+'RÍGIDO-Anexo 2 (A)'!U23 -> 112 | F11: =+E11/2 -> 56 | G11: =(E11+F11)*0.0625 -> 10.5 | H11: Aula
B12: Nutrición y dietética en el ciclo de vida I | C12: LNCS-316 | E12: =+'RÍGIDO-Anexo 2 (A)'!AA23 -> 112 | F12: =+E12/2 -> 56 | G12: =(E12+F12)*0.0625 -> 10.5 | H12: Aula
B13: Bioquímica metabólica II | C13: LNCS-422 | D13: LNCS-315 | E13: =+'RÍGIDO-Anexo 2 (A)'!O29 -> 96 | F13: =+E13/2 -> 48 | G13: =(E13+F13)*0.0625 -> 9 | H13: Aula / Laboratorio
B14: Nutrición y dietética en el ciclo de vida II | C14: LNCS-423 | D14: LNCS-316 | E14: =+'RÍGIDO-Anexo 2 (A)'!U29 -> 96 | F14: =+E14/2 -> 48 | G14: =(E14+F14)*0.0625 -> 9 | H14: Aula
B15: Fisiopatología | C15: LNCS-530 | E15: =+'RÍGIDO-Anexo 2 (A)'!U35 -> 96 | F15: =+E15/2 -> 48 | G15: =(E15+F15)*0.0625 -> 9 | H15: Aula / Laboratorio
B16: Proceso de cuidado nutricional | C16: LNCS-531 | E16: =+'RÍGIDO-Anexo 2 (A)'!AA35 -> 112 | F16: =+E16/2 -> 56 | G16: =(E16+F16)*0.0625 -> 10.5 | H16: Aula
B17: Calidad de la atención y seguridad del paciente | C17: LNCS-534 | E17: =+'RÍGIDO-Anexo 2 (A)'!AS35 -> 112 | F17: =+E17/2 -> 56 | G17: =(E17+F17)*0.0625 -> 10.5 | H17: Aula / Laboratorio
B18: Nutrición en situaciones especiales de salud | C18: LNCS-635 | E18: =+'RÍGIDO-Anexo 2 (A)'!C41 -> 112 | F18: =+E18/2 -> 56 | G18: =(E18+F18)*0.0625 -> 10.5 | H18: Aula
B19: Clínica de dietoterapia I | C19: LNCS-638 | E19: =+'RÍGIDO-Anexo 2 (A)'!U41 -> 112 | F19: =+E19/2 -> 56 | G19: =(E19+F19)*0.0625 -> 10.5 | H19: Aula / Laboratorio
B20: Farmacología aplicada a la nutrición | C20: LNCS-639 | E20: =+'RÍGIDO-Anexo 2 (A)'!AA41 -> 96 | F20: =+E20/2 -> 48 | G20: =(E20+F20)*0.0625 -> 9 | H20: Aula / Laboratorio
B21: Nutrición y ejercicio físico | C21: LNCS-642 | E21: =+'RÍGIDO-Anexo 2 (A)'!AS41 -> 96 | F21: =+E21/2 -> 48 | G21: =(E21+F21)*0.0625 -> 9 | H21: Aula / Laboratorio
B22: Clínica de dietoterapia II | C22: LNCS-745 | D22: LNCS-638 | E22: =+'RÍGIDO-Anexo 2 (A)'!O47 -> 128 | F22: =+E22/2 -> 64 | G22: =(E22+F22)*0.0625 -> 12 | H22: Aula / Laboratorio
B23: Integración de prácticas en nutrición clínica | C23: LNCS-853 | E23: =+'RÍGIDO-Anexo 2 (A)'!O53 -> 128 | F23: =+E23/2 -> 64 | G23: =(E23+F23)*0.0625 -> 12 | H23: Aula / Clínica de nutrición
B24: Manejo integral de la obesidad | C24: LNCS-854 | E24: =+'RÍGIDO-Anexo 2 (A)'!U53 -> 96 | F24: =+E24/2 -> 48 | G24: =(E24+F24)*0.0625 -> 9 | H24: Aula
B25: Integración de prácticas en nutrición poblacional | C25: LNCS-855 | E25: =+'RÍGIDO-Anexo 2 (A)'!AA53 -> 128 | F25: =+E25/2 -> 64 | G25: =(E25+F25)*0.0625 -> 12 | H25: Aula
B26: Fundamentos de nutrición enteral y parenteral. | C26: LNCS-857 | E26: =+'RÍGIDO-Anexo 2 (A)'!AM53 -> 128 | F26: =+E26/2 -> 64 | G26: =(E26+F26)*0.0625 -> 12 | H26: Aula / Laboratorio
A27: Ciencias naturales y de alimentos | B27: Química de la nutrición | C27: LNCA-103 | E27: =+'RÍGIDO-Anexo 2 (A)'!O11 -> 128 | F27: =+E27/2 -> 64 | G27: =(E27+F27)*0.0625 -> 12 | H27: Aula / Laboratorio
B28: Biología celular | C28: LNCA-104 | E28: =+'RÍGIDO-Anexo 2 (A)'!U11 -> 128 | F28: =+E28/2 -> 64 | G28: =(E28+F28)*0.0625 -> 12 | H28: Aula / Laboratorio
B29: Química de alimentos | C29: LNCA-210 | E29: =+'RÍGIDO-Anexo 2 (A)'!AA17 -> 128 | F29: =+E29/2 -> 64 | G29: =(E29+F29)*0.0625 -> 12 | H29: Aula / Laboratorio
B30: Alimentos y bebidas nacionales e internacionales | C30: LNCA-314 | E30: =+'RÍGIDO-Anexo 2 (A)'!O23 -> 112 | F30: =+E30/2 -> 56 | G30: =(E30+F30)*0.0625 -> 10.5 | H30: Aula / Laboratorio
B31: Microbiología de alimentos | C31: LNCA-318 | E31: =+'RÍGIDO-Anexo 2 (A)'!AM23 -> 112 | F31: =+E31/2 -> 56 | G31: =(E31+F31)*0.0625 -> 10.5 | H31: Aula / Laboratorio
B32: Producción de alimentos y técnicas culinarias | C32: LNCA-424 | E32: =+'RÍGIDO-Anexo 2 (A)'!AA29 -> 128 | F32: =+E32/2 -> 64 | G32: =(E32+F32)*0.0625 -> 12 | H32: Aula / Laboratorio
B33: Análisis de alimentos | C33: LNCA-425 | E33: =+'RÍGIDO-Anexo 2 (A)'!AG29 -> 128 | F33: =+E33/2 -> 64 | G33: =(E33+F33)*0.0625 -> 12 | H33: Aula / Laboratorio
B34: Tecnología de alimentos con compromiso social | C34: LNCA-533 | E34: =+'RÍGIDO-Anexo 2 (A)'!AM35 -> 96 | F34: =+E34/2 -> 48 | G34: =(E34+F34)*0.0625 -> 9 | H34: Aula / Laboratorio
B35: Desarrollo e innovación de productos alimentarios | C35: LNCA-641 | E35: =+'RÍGIDO-Anexo 2 (A)'!AM41 -> 112 | F35: =+E35/2 -> 56 | G35: =(E35+F35)*0.0625 -> 10.5 | H35: Aula / Laboratorio
B36: Alimentación sostenible | C36: LNCA-747 | E36: =+'RÍGIDO-Anexo 2 (A)'!AA47 -> 80 | F36: =+E36/2 -> 40 | G36: =(E36+F36)*0.0625 -> 7.5 | H36: Aula
B37: Aseguramiento de calidad e inocuidad de alimentos | C37: LNCA-748 | E37: =+'RÍGIDO-Anexo 2 (A)'!AG47 -> 96 | F37: =+E37/2 -> 48 | G37: =(E37+F37)*0.0625 -> 9 | H37: Aula / Clínica de nutrición
B38: Alimentos funcionales | C38: LNCA-750 | E38: =+'RÍGIDO-Anexo 2 (A)'!AS47 -> 96 | F38: =+E38/2 -> 48 | G38: =(E38+F38)*0.0625 -> 9 | H38: Aula / Laboratorio
B39: Integración de prácticas en nutrición clínica | C39: LNB-801 | F39: =+E39/2 -> 0 | G39: =(E39+F39)*0.0625 -> 0 | H39: Clínica de nutrición
B40: Manejo integral de la obesidad y síndrome metabólico | C40: LNB-803 | E40: 80 | F40: =+E40/2 -> 40 | G40: =(E40+F40)*0.0625 -> 7.5 | H40: Aula / Clínica de nutrición
B41: Nutrición y ejercicio físico | C41: OPT-501 | E41: 48 | F41: =+E41/2 -> 24 | G41: =(E41+F41)*0.0625 -> 4.5 | H41: Aula / Laboratorio
...

Sheet Instrucciones para el llenado
H1: Anexo 2
C2: "MAPA CURRICULAR"
A3: INDICACIONES:
A4: Exhibir la información de los planes de estudio, coforme a los siguientes supuestos y atendiendo las indicaciones para el llenado de cada formato:
A5: 1) DISEÑO CURRICULAR RÍGIDO: | C5: Son planes de estudio organizados en ciclos escolares. | E5: Emplear el formato de la hoja denominada "RÍGIDO-Anexo 2 (A)".
E6: Si cuenta con asignaturas optativas; únicamente deberá indicar el dato "optativa" en el rubro tipo de asignatura del formato "RÍGIDO-Anexo 2 (A)", y la información restante deberá señalarla en el formato "OPTATIVAS-Anexo 2 (A)".
A7: 2) DISEÑO CURRICULAR FLEXIBLE: | C7: Considera planes de estudio en el que sus asignaturas se encuentran organizadas en áreas o módulos. | E7: Exhibir el formato de la hoja denominada "FLEXIBLE-Anexo 2 (B)". Además, es indispensable emplear el formato "RÍGIDO-Anexo 2 (A)" para ilustrar la trayectoria académica que seguirán los estudiantes; es decir, el ideal de mapa curricular.
G12: RÍGIDO-Anexo 2 (A)
B14: MAPA CURRICULAR
A16: APARTADO | C16: DESCRIPCIÓN
A17: Ciclo escolar | C17: Indicar el tipo y número de ciclo en el que los estudiantes cursarán cada asignatura. En el ejemplo, se indica entre paréntesis los distintos tipos de ciclos; elegir el correspondiente al plan de estudios y omitir los restantes.
A18: Tipo de asignatura o unidad de aprendizaje | C18: Señalar si es obligatoria u optativa.
A19: Denominación de asignatura o unidad de aprendizaje | C19: Especificar el nombre con el que se identifica a cada asignatura. Elegir de acuerdo a la disciplina o campo de estudio y evitar el uso de abreviaturas o terminología extranjera.
A20: Clave de asignatura o unidad de aprendizaje | C20: Identificar de manera numérica o alfanumérica cada asignatura.
A21: Seriación | C21: Enunciar la clave de la asignatura que previamente debió cursarse y que determina la secuencia temática con la actual.
A22: Horas bajo conducción de un académico | C22: Establecer el número de horas-clase que se dedicará por ciclo a la asignatura. Considerar horas completas.
A23: Horas independientes | C23: Proponer el número de horas que dedica el alumno por ciclo para su estudio independiente.
A24: Créditos | C24: Indicar el número de créditos establecidos para cada asignatura. Considerar 0.0625 por cada hora destinada al desarrollo de las actividades bajo conducción de un académico e independientes por ciclo.
A25: Tipo de instalaciones | C25: Especificar el tipo de instalación (incluyendo especiales) que empleará para el desarrollo de las actividades de aprendizaje bajo la conducción de un académico. Vincular con la modalidad educativa.
A27: NOTA: Los espacios en el mapa curricular deberán corresponder con el número de ciclos y asignaturas que comprenden el plan de estudios. Agregar u omitir espacios, de acuerdo a sus necesidades.
A28: Los colores de la representación en miniatura del mapa curricular únicamente son un referente ilustrativo para la ubicación de la información; por lo que se puede prescindir de ellos. En cambio, para la clasificación de las áreas en currículo flexible, se recomienda mantener los colores representados.
G30: OPTATIVAS-Anexo 2 (A)
B32: Apartado: ASIGNATURAS OPTATIVAS
A34: APARTADO | C34: DESCRIPCIÓN
A35: Ciclo escolar | C35: Indicar el tipo y número de ciclo en el que los estudiantes podrán cursar la asignatura.
A36: Denominación de asignatura o unidad de aprendizaje | C36: Especificar el nombre con el que se identifica a cada una de las asignaturas. Elegir de acuerdo a la disciplina o campo de estudio y evitar el uso de abreviaturas o terminología extranjera.
A37: Clave de asignatura o unidad de aprendizaje | C37: Identificar de manera numérica o alfanumérica cada una de las asignaturas.
A38: Seriación | C38: Enunciar la clave de la asignatura que previamente debió cursarse y que determina la secuencia temática con la actual.
A39: Horas bajo conducción de un académico | C39: Establecer el número de horas-clase que se dedicará por ciclo a la asignatura. Considerar horas completas.
A40: Horas independientes | C40: Proponer el número de horas que dedica el alumno por ciclo para su estudio independiente.
A41: Créditos | C41: Indicar el número de créditos establecidos para cada asignatura. Considerar 0.0625 por cada hora destinada al desarrollo de las actividades bajo conducción de un académico e independientes por ciclo.
A42: Tipo de instalaciones | C42: Especificar el tipo de instalación (incluyendo especiales) que empleará para el desarrollo de las actividades de aprendizaje bajo la conducción de un académico. Vincular con la modalidad educativa.
A44: NOTA: El número de filas dependerá de la cantidad de asignaturas optativas que se oferten para el plan de estudios.
B48: Apartado: REQUERIMIENTOS MÍNIMOS PARA LAS ASIGNATURAS OPTATIVAS
A50: APARTADO | C50: DESCRIPCIÓN
A51: Horas bajo conducción de un académio | C51: Indicar el número mínimo de horas bajo condución de un académico que se deberán cumplimentar en las asignaturas optativas.
A52: Créditos | C52: Señalar el número mínimo de crédios que se deberán cumplimentar en las asignaturas optativas.
B56: Apartado: TOTAL DE ASIGNATURAS QUE INTEGRAN EL PLAN DE ESTUDIOS
A58: APARTADO | C58: DESCRIPCIÓN
A59: Horas bajo conducción de un académico | C59: Establecer el total de horas-clase que se dedicará a las asignaturas obligatorias y optativas, respectivamente.
...
